Workbook

Sheet BOM
A1: Shiniji BOM Entry Template
A2: 1 ไฟล์ = 1 เมนู · กรอกในช่องสีเหลืองเท่านั้น · ห้ามแก้ช่องอื่น
A4: ชื่อเมนู (ไทย) * | B4: แซลมอนซาชิมิ 5 คำ | G4: ← ตัวอย่าง
A5: ชื่อเมนู (อังกฤษ)
A6: หมวดเมนู (ถ้าเป็นเมนูใหม่)
A7: รหัสเมนู (ถ้ามีอยู่แล้ว ไม่บังคับ)
A9: หมายเหตุ: ถ้าเมนูนี้มีอยู่แล้ว ใส่รหัสในช่อง B7 (ทีมงานจะดูจากรหัส ไม่ใช้ชื่อ) แล้วเว้น B6 ว่างไว้ได้
A11: หมวด (CAT) | B11: วัตถุดิบ | C11: Qty | D11: หน่วย (auto) | E11: Yield % เริ่มต้น (auto) | F11: Yield % ที่ใช้จริง (เว้นว่าง = ใช้ค่าเริ่มต้น)
A12: Fish | B12: 1101010001 | ปลาแซลมอน (5-6กก/ตัว) (Salmon Fresh) | C12: 500 | D12: =IFERROR(INDEX(ItemMaster!$C:$C,MATCH(LEFT(B12,FIND(" | ",B12)-1),ItemMaster!$A:$A,0)),"") -> g | E12: =IFERROR(INDEX(ItemMaster!$D:$D,MATCH(LEFT(B12,FIND(" | ",B12)-1),ItemMaster!$A:$A,0)),"") -> 58 | G12: ← ตัวอย่าง (ลบแถวนี้ทิ้ง หรือแก้ทับได้เลย)
D13: =IFERROR(INDEX(ItemMaster!$C:$C,MATCH(LEFT(B13,FIND(" | ",B13)-1),ItemMaster!$A:$A,0)),"") | E13: =IFERROR(INDEX(ItemMaster!$D:$D,MATCH(LEFT(B13,FIND(" | ",B13)-1),ItemMaster!$A:$A,0)),"")
D14: =IFERROR(INDEX(ItemMaster!$C:$C,MATCH(LEFT(B14,FIND(" | ",B14)-1),ItemMaster!$A:$A,0)),"") | E14: =IFERROR(INDEX(ItemMaster!$D:$D,MATCH(LEFT(B14,FIND(" | ",B14)-1),ItemMaster!$A:$A,0)),"")
D15: =IFERROR(INDEX(ItemMaster!$C:$C,MATCH(LEFT(B15,FIND(" | ",B15)-1),ItemMaster!$A:$A,0)),"") | E15: =IFERROR(INDEX(ItemMaster!$D:$D,MATCH(LEFT(B15,FIND(" | ",B15)-1),ItemMaster!$A:$A,0)),"")
D16: =IFERROR(INDEX(ItemMaster!$C:$C,MATCH(LEFT(B16,FIND(" | ",B16)-1),ItemMaster!$A:$A,0)),"") | E16: =IFERROR(INDEX(ItemMaster!$D:$D,MATCH(LEFT(B16,FIND(" | ",B16)-1),ItemMaster!$A:$A,0)),"")
D17: =IFERROR(INDEX(ItemMaster!$C:$C,MATCH(LEFT(B17,FIND(" | ",B17)-1),ItemMaster!$A:$A,0)),"") | E17: =IFERROR(INDEX(ItemMaster!$D:$D,MATCH(LEFT(B17,FIND(" | ",B17)-1),ItemMaster!$A:$A,0)),"")
D18: =IFERROR(INDEX(ItemMaster!$C:$C,MATCH(LEFT(B18,FIND(" | ",B18)-1),ItemMaster!$A:$A,0)),"") | E18: =IFERROR(INDEX(ItemMaster!$D:$D,MATCH(LEFT(B18,FIND(" | ",B18)-1),ItemMaster!$A:$A,0)),"")
D19: =IFERROR(INDEX(ItemMaster!$C:$C,MATCH(LEFT(B19,FIND(" | ",B19)-1),ItemMaster!$A:$A,0)),"") | E19: =IFERROR(INDEX(ItemMaster!$D:$D,MATCH(LEFT(B19,FIND(" | ",B19)-1),ItemMaster!$A:$A,0)),"")
D20: =IFERROR(INDEX(ItemMaster!$C:$C,MATCH(LEFT(B20,FIND(" | ",B20)-1),ItemMaster!$A:$A,0)),"") | E20: =IFERROR(INDEX(ItemMaster!$D:$D,MATCH(LEFT(B20,FIND(" | ",B20)-1),ItemMaster!$A:$A,0)),"")
D21: =IFERROR(INDEX(ItemMaster!$C:$C,MATCH(LEFT(B21,FIND(" | ",B21)-1),ItemMaster!$A:$A,0)),"") | E21: =IFERROR(INDEX(ItemMaster!$D:$D,MATCH(LEFT(B21,FIND(" | ",B21)-1),ItemMaster!$A:$A,0)),"")
D22: =IFERROR(INDEX(ItemMaster!$C:$C,MATCH(LEFT(B22,FIND(" | ",B22)-1),ItemMaster!$A:$A,0)),"") | E22: =IFERROR(INDEX(ItemMaster!$D:$D,MATCH(LEFT(B22,FIND(" | ",B22)-1),ItemMaster!$A:$A,0)),"")
D23: =IFERROR(INDEX(ItemMaster!$C:$C,MATCH(LEFT(B23,FIND(" | ",B23)-1),ItemMaster!$A:$A,0)),"") | E23: =IFERROR(INDEX(ItemMaster!$D:$D,MATCH(LEFT(B23,FIND(" | ",B23)-1),ItemMaster!$A:$A,0)),"")
D24: =IFERROR(INDEX(ItemMaster!$C:$C,MATCH(LEFT(B24,FIND(" | ",B24)-1),ItemMaster!$A:$A,0)),"") | E24: =IFERROR(INDEX(ItemMaster!$D:$D,MATCH(LEFT(B24,FIND(" | ",B24)-1),ItemMaster!$A:$A,0)),"")
... D41: =IFERROR(INDEX(ItemMaster!$C:$C,MATCH(LEFT(B41,FIND(" | ",B41)-1),ItemMaster!$A:$A,0)),"") | E41: =IFERROR(INDEX(ItemMaster!$D:$D,MATCH(LEFT(B41,FIND(" | ",B41)-1),ItemMaster!$A:$A,0)),"")

Sheet Lookup
A1: CategoryDisplay | B1: SafeName | D1: CAT_1 | E1: CAT_2 | F1: CAT_3 | G1: CAT_4 | H1: CAT_5 | I1: CAT_6 | J1: CAT_7 | K1: CAT_8 | L1: CAT_9 | M1: CAT_10 | N1: CAT_11 | O1: CAT_12 | P1: CAT_13 | Q1: CAT_14 | R1: CAT_15 | S1: CAT_16 | T1: CAT_17 | U1: CAT_18 | V1: CAT_19 | W1: CAT_20 | X1: CAT_21 | Y1: CAT_22 | Z1: CAT_23 | AA1: CAT_24 | AB1: CAT_25 | AC1: CAT_26 | AD1: CAT_27 | AE1: CAT_28 | AF1: CAT_29 | AG1: CAT_30 | AH1: CAT_31 | AI1: CAT_32
A2: Beef | B2: CAT_1 | D2: 1101070009 | ลิ้นวัวอาร์เจนติน่า (kg) (Beef Tongue) (Argentine) | E2: 1101120001 | ครีมชีส (2กก/ก้อน) (Cream Cheese) (Caroline) | F2: 1202060901 | FG.กาแฟสกัดเย็น (1ลิตร) (Cold Brew) | G2: 1101290001 | น้ำมันคาโนล่า (1ลิตร/ขวด) (Canola Oil) (Naturel) | H2: 1101040001 | กระดองปูหิมะ (10pcs/pack) (กระดองปูหิมะ) (Zuwai Kani Koura) | I2: 1101200001 | Cheese -Holiday Twist Bagel | J2: 1202100006 | Erdinger Braohaus | K2: 1101210001 | กะทิ (250มล/กล่อง) (Coconut Milk) (Aroy-D) | L2: 1101110002 | ไข่นกกระทา (50ฟอง/แพ็ค) (Quail Eggs) (Aro) | M2: 1101010003 | FG.หัวปลาแซลมอนสด (หัว) | N2: 1202010001 | กล้วยหอมทองหั่นแว่นแช่แข็ง ( _ _กก/แพ็ค) (Banana Slices) ( Golden) | O2: 1202020001 | น้ำตาลสด จากช่อดอกต้นมะพร้าว (325มล/ขวด) (Coconut Blossom Nectar Juice) (Reua Thong) | P2: 1202070001 | CLX_คุกกิ้งครีม (1ลิตร/กล่อง) (Cooking Cream) (Millac Gold) | Q2: 1101180001 | บะหมี่เหลือง ไทเป สูตร 2 (1kg/pack) (Egg Noodle Taipei) | R2: 1101080001 | ขั้วตับหมู เบทาโกร (1kg/pack) (Pork Diaphragm) (BTG) | S2: 1101090002 | กึ๋นไก่ (kg) (CK Gizzards) | T2: 1101150008 | ปลาโอท้องแถบแห้งเส้น (50g/pack) (Dried Bonito Flakes) (MK) | U2: 1101160003 | ขิงดอง สีขาว (1kg/pack) (Pickled Ginger) (Gari Shoga White) | V2: 1202090002 | Kirin Beer (330ml/bt) (Kirin Beer) | W2: 1101190001 | ข้าวญี่ปุ่น กิโมโน (5kg/pack) (Japanese Rice Kimono) (Mahanakorn) | X2: 1101020001 | ไข่กุ้งอิบิโกะ (500g/pack) (Capelin Roe Fz.) (Ebiko Orange) | Y2: 1202110001 | | Z2: 1101280062 | คุกกิ้งครีม (1ลิตร/กล่อง) (Cooking Cream) (Millac Gold) | AA2: 1101030001 | กุ้งขาวจัมโบ้ (21-25ตัว/กก.) (White Shrimp) | AB2: 1202080006 | น้ำดื่ม สปริงเคิล (12x500มล/แพ็ค) (Sprinkle Drinking Water) | AC2: 1202040001 | FG.น้ำเชื่อม (1ลิตร) (FG.Natural Cane Syrup) | AD2: 1101060001 | ปลาหมึกหอมญี่ปุ่น (อาโอริอิกะ) (kg) (Aori Ika) | AE2: 1202050004 | คาราเมลกรอบ (_ _กรัม/แพ็ค) (Dalgona Candy) (Spongy Candy) | AF2: 1101050004 | หอยปีกนก M. (51-70pcs/kg/pack) (Hokki Gai) | AG2: 1101140007 | กระเจี๊ยบ ผักอินทรีย์ (kg) (Okra Organic) | AH2: 1101170001 | วาซาบิสับดอง (250g/pack) (Wasabi Chopped Shoyu Zuke Fz.) | AI2: 1202120001 | รีเจนซี่ บรั่นดี (350มล/ขวด) (Regency Brandy)
A3: Cheese/Butter | B3: CAT_2 | D3: 1101070002 | เนื้อพิคานญ่า ส่วนสะโพก (kg) (Picanha Aus.) (MB 2/3 RUMP CAP) | E3: 1101120003 | ชีสพาร์เมซานชนิดขูด (454g/pack) (Parmesan Cheese Grated) (Schreiber) | F3: 1202060902 | FG.เบทชาไทย (1ลิตร) (Thai Tea Base) | G3: 1101290002 | น้ำมันคาโนล่า (5ลิตร/ขวด) (Canola Oil) (Naturel) | H3: 1101040006 | ขาปูทาราบะ | I3: 1101200002 | Luxe Holiday Macaron | J3: 1202100004 | Erdinger Brauhaus Radler 2.6% (30ltr/keg) | K3: 1101210003 | ข้าวคั่วป่น (500กรัม/แพ็ค) (Roasted Rice Ground) | L3: 1101110003 | ไข่เค็มต้ม (ฟอง) (Salted Eggs Boiled) (Aro) | M3: 1101010002 | FG.เนื้อปลาแซลมอนสดแล่ (กก) (FG.Salmon Fillet Fresh) (แล่โดย.Chef) | N3: 1202010005 | บลูเบอร์รี่สด จัมโบ้ (125กรัม/แพ็ค) (Blueberries Fresh Jumbo Size) | O3: 1202020005 | น้ำผลไม้รวม (700มล/ขวด) (Mixed Fruit Juice) (Sunquick) | P3: 1202070901 | FG.นมผสม (3กก/สูตร) (Mixed Milk) (1:2 นมจืด+ข้น) | Q3: 1101180010 | วุ้นเส้น (40กรัมx10ถุง/แพ็ค) (Bean Vermicelli) (ต้นสน) | R3: 1101080002 | คอหมูสำหรับย่าง เบทาโกร (1kg/pack) (Pork Collar for Grilling) | S3: 1101090004 | ตับไก่ ซีพี (1kg/pack) (CK Liver Slice) | T3: 1101150009 | ปลาโออบแห้ง สไลด์ เอ็มเค (400g/pack) (Dried Bonito Slice) (MK) | U3: 1101160002 | ขิงดองซอย สีแดง (1kg/pack) (Pickled Ginger Red) (Beni Shoga) | V3: 1202090001 | Pineapple Cider (355ml/bt) (ACE) | W3: 1101190002 | ข้าวญี่ปุ่น โคชิ (5kg/pack) (Japanese Rice Koshihikari) (Fujisan) | X3: 1101020002 | ไข่ปลาคาเวียร์ โอเชียสตร้า (_ _g/each) (Oscietra Caviar) | Y3: 1202110019 | สาเก Kazenomari Akitsuho Junmai (720ml/bt) | Z3: 1101280009 | ซอสงา (150g/pack) (Sesame Dipping Sauce) (Pure Foods) | AA3: 1101030004 | กุ้งหวาน 3L (45-50pcs/kg/box) (Ama Ebi 3L.) | AB3: 1202080007 | น้ำดื่ม สปริงเคิล (6x1500มล/แพ็ค) (Sprinkle Drinking Water) | AC3: 1202040002 | ท็อปปิ้ง คาราเมล (1.2กก/กระปุก) (Topping Caramel) (Juniper) | AD3: 1101060002 | หนวดหมึกยักษ์แช่แข็ง (1kg/pack) (Giant Squid Tentacles Fz.) | AE3: 1202050003 | คุกกี้แซนวิช รสช็อกโกแลต (12ชิ้นx27.6กรัม/กล่อง) (Sandwich Cookies w/Vanilla Flavored Cream) (Oreo) | AF3: 1101050002 | หอยเชลล์แช่แข็ง M.(26-30pcs/kg/pack) (Scallop M.) (Sashimi) | AG3: 1101140009 | กระเทียมจีนตัดจุก (kg) (Chinese Garlic Top-cut ) | AH3: 1101170002 | วาซาบิแช่แข็ง (500g/pack) (Wasabi Paste Fz.) (Wasabi-O) | AI3: 1202120002 | รีเจนซี่ บรั่นดี (550มล/ขวด) (Regency Brandy)
A4: Coffee/Tea | B4: CAT_3 | D4: 1101070003 | เนื้อพิคานย่า Aus.100วัน (kg) (Picanha Aus.) (Sirloin Cap/Rump Cap 100 Days.) | E4: 1101120002 | ชีสเชดด้า (24 แผ่น/500กรัม/แพ็ค) (Cheddar Cheese) (Imperial) | F4: 1202060903 | FG.เบทชาไทย (1ลิตร) (Thai Tea Base) (Mixed Berries) | G4: 1101290003 | น้ำมันปาล์ม (12ถุงx1ลิตร/ลัง) (Palm Oil) (Gaysorn) | H4: 1101040004 | ปูนิ่มแช่แข็ง (4-6 ตัว/กก) (Soft Shell Crab fz.) | I4: 1101200201 | ขนมปังเกลือสไตล์ญี่ปุ่น (ea) (Shio Pan-92) | J4: 1202100001 | Guava Craft Cider 5.0% (20ltr/keg) (ACE) | K4: 1101210004 | งาขาว (500กรัม/แพ็ค) (Sesame Seed White) | L4: 1101110001 | ไข่ไก่ No.2 (30ฟอง/แผง) (Egg No.2) (Aro) | M4: 1101010011 | ครีบปลากระเบนแช่เข็ง 13-16 cm (500g/Pack) (Stingray Fin Fz.) (Ei Hire) | N4: 1202010007 | บ๊วยดอง (1.8กก/กระปุก) (pickled Plum) (Aro) | O4: 1202020002 | น้ำผลไม้เข้มข้น Tropical Fruit (1ลิตร/ขวด) (Tropical Fruit Based Preparation) (Synova) | P4: 1102070015 | กรีกโยเกิร์ต (กก) (Greek Yogurt) | Q4: 1101180006 | เส้นยากิโซบะ (500g/pack) (Yakisoba Noodles) | R4: 1101080003 | คอหมูอัดแท่งแช่แข็ง B-2 เบทาโกร (1kg/pack) (Pork Collar Fz.) | S4: 1101090007 | บั้นท้ายไก่ (kg) (CK Butts) | T4: 1101150006 | ปูอัด (500g/pack) (Crab Sticks) (Kani Kama) | U4: 1101160004 | ซุปมิโซะ (1kg/pack) (Miso Paste Marukome) (Ikkyu San) | W4: 1101190003 | ข้าวหอมมะลิ ใหม่ (49kg/pack) (Jasmine Rice) (ไดโนเสาร์) | X4: 1101020003 | ไข่ปลาคาเวียร์ดำ (80g/each) (Lumpfish Caviar Black) | Y4: 1202110005 | สาเก คุโบตะ จุนไม ไดกินโจ (300ml/bt) (Kubota Junmai Daiginjo) (ASH) | Z4: 1101280010 | ซอสชูโน (500กรัม/ขวด) (Chunou Sauce) (Bulldog) | AA4: 1101030005 | กุ้งหวานญี่ปุ่น (52pcs/2kg/pack) (Amaebi) | AB4: 1202080008 | น้ำแร่ธรรมชาติ มองต์เฟลอ (24x330มล/แพ็ค) (Mineral Water Mont Fleur) | AC4: 1202040003 | ท็อปปิ้ง ช็อกโกแลต (1.2กก/กระปุก) (Topping Chocolate) (Juniper) | AD4: 1101060003 | หมึกทาโกะต้มแช่แข็ง (kg) (Tako Boiled Fz.) (Octopus Boiled) | AE4: 1202050005 | บ๊วยดอง (1.8กก/กระปุก) (pickled Plum) (Aro) | AF4: 1101050003 | หอยเชลล์แช่แข็ง Size Mini (300-400pcs/kg/pack) (Scallop) | AG4: 1101140008 | กระเทียมจีนปอกเปลือก (kg) (Garlic Chinese Peeled)
A5: Cooking Oil | B5: CAT_4 | D5: 1101070004 | เนื้อพิคานย่า Aus.150วัน (kg) (Picanha Aus.) (Sirloin Cap/Rump Cap 150 Days.) | E5: 1101120004 | เนยสด ชนิดจืด (5กก/ก้อน) (Butter Unsatlted) (Allowrie) | F5: 1202060904 | กาแฟ MYANMAR+BRAZIL 1000g | G5: 1101290004 | น้ำมันปาล์ม (13.75ลิตร/ปี๊บ) (Palm Oil) (Bonus) | H5: 1101040005 | ปูนิ่มแช่แข็ง (6 ตัว/กก) (Soft Shell Crab fz.) | I5: 1101200202 | ชิโอะปัน (ชิโอะปัน) | J5: 1202100005 | Hard Candy Mulberry Sorbet 4.0% (20ltr/keg) | K5: 1101210005 | งาขาวคั่ว (1กก/แพ็ค) (White Sesame Seeds Roasted) (Irigoma Shiro/Makoto) | M5: 1101010012 | ครีบปลาตาเดียวแช่แข็ง (1kg/pack) (Engawa Fz) | N5: 1202010008 | พีชผ่าครึ่งในน้ำเชื่อม (850กรัม/กระป๋อง) (Peach Halves in Syrup) (Ligo) | O5: 1202020003 | น้ำผลไม้เข้มข้น รสบ็วย (1ลิตร/ขวด) (Plum Fruit Based Preparation) (Synova) | P5: 1202070002 | ครีมเทียมข้นหวาน (2กก/ถุง) (Sweetened Condensed Creamer) (Carnation) | Q5: 1101180007 | เส้นสปาเก็ตตี้ No. (3kg/pack) (Spaghetti No.3) (Agnesi) | R5: 1101080004 | ซี่โครงหมูอ่อน (kg) (Baby Back Ribs) | S5: 1101090008 | ปีกเต็มไก่แช่แข็ง (kg) (CK Wing Whole Fz.) | T5: 1101150007 | ปูอัดพรีเมี่ยม (10x500g/carton) (Crab Sticks Fz.) (Kanikama Fz.) | U5: 1101160005 | ต้นขิงดอง (50pcs/200g/pack) (Pickled Ginger Stalks) (Hajikami) | W5: 1101190004 | แป้งข้าวจ้าว (1กก/แพ็ค) (Rice Flour) (ช้างสามเศียร) | X5: 1101020004 | ไข่ปลาคาเวียร์ดำแช่แข็ง (_ _g/each) (Black Caviar Fz.) | Y5: 1202110006 | สาเก คุโบตะ จุนไม ไดกินโจ (720ml/bt) (Kubota Junmai Daiginjo) (ASH) | Z5: 1101280011 | ซอสถั่วเหลือง คิโคแมน (18ลิตร/กล่อง) (Kikkoman Soy Sauce) (Kikkoman) | AA5: 1101030006 | กุ้งหวานแบบมีหัวแช่แข็ง (L) (15-19pcs/kg/box) (Botan Ebi ,J with Head) | AB5: 1202080003 | เป๊ปซี่ กระป๋อง (24x325มล/แพ็ค) (Pepsi Can) | AC5: 1202040004 | ท็อปปิ้ง บลูเบอร์รี่ (1.2กก/กระปุก) (Topping Blueberry) (Juniper) | AE5: 1202050008 | ริชส์ นอนแดรี่ ครีมเมอร์ 454 ก. | AF5: 1101050001 | เนื้อหอยเชลล์ซาชิมิแช่แข็ง Size M. (26-30pcs/pack) (Hotate Sashimi Size M.Fz.) | AG5: 1101140010 | กระเทียมต้น (300กรัม/แพ็ค) (Leek) (RPF)
A6: Crab | B6: CAT_5 | D6: 1101070005 | เนื้อพิคานย่า แองกัส (kg) (Angus Picanha) (Sirloin Cap/Rump Cap) | F6: 1102060904 | กาแฟเมล็ด (1กก/แพ็ค) (Coffee Beans Dark Roast) (El Carmen) | G6: 1101290005 | น้ำมันปาล์ม (18ลิตร/ปี๊บ) (Palm Oil) (Gaysorn) | H6: 1101040002 | เนื้อปูเทียมอัด Size 18 ซม. (1kg/pack) (Kani Kama) | I6: 1101200203 | ดัลโกน่า แคนดี้ ทอฟฟี่ (Dalgona Candy Toffee) | J6: 1202100003 | Pineapple Cider 5% (20ltr/keg) (ACE) | K6: 1101210006 | งาดำ (500กรัม/แพ็ค) (Sesame Seed Black) | M6: 1101010013 | ครีบปลาตาเดียวแช่แข็ง 3-4 ซม. (1kg/pack) (Engawa Fz) | N6: 1202010011 | มะนาวสีเหลือง (กก) (200กรัม/ลูก) (Lemon Yellow) | O6: 1202020004 | น้ำผลไม้เข้มข้น รสลิ้นจี่ (1ลิตร/ขวด) (ychee Fruit Based Preparation) | P6: 1202070003 | นมข้นจืด (1กก/แพ็ค) (Condensed Milk) (Carnation) | Q6: 1101180009 | เส้นสปาเก็ตตี้ คาเปลลินี No.1 (500กรัม/แพ็ค) (Spaghetti Capellini ( Agnesi) | R6: 1101080005 | สันคอหมู เบทาโกร (kg) (Pork Collar) | S6: 1101090009 | ปีกไก่กลาง (kg) (CK Medium Wings) | T6: 1101150010 | ลูกชิ้นเนื้อ (500g/pack) (Beef Ball) (Numchai) | U6: 1101160007 | ต้นไผ่ ขิงดองสามรสสีธรรมชาติแบบสไลซ์ (700g/pack) (Pickled Ginger Bamboo Sliced) | W6: 1101190005 | แป้งข้าวโพด (1กก/แพ็ค) (Corn Flour) (.) | X6: 1101020006 | ไข่ปลาบินแช่แข็ง (โทบิโกะ) (500g/pack) (Flying Fish Roe) (Tobikko Orange) | Y6: 1202110009 | สาเก คูโบตะ มันจู (300ml/bt) (Kubota Manju) (ASH) | Z6: 1101280012 | ซอสถั่วเหลืองญี่ปุ่น โทคุเซ็น (1ลิตร/ขวด) (Tokusen Japanese Soy Sauce) (Yamamori) | AA6: 1101030002 | กุ้งแดงอาร์เจนตินา (_ _pcs/kg) (Red Shrimp Argentine) | AB6: 1202080004 | เป๊ปซี่ ไม่มีน้ำตาล กระป๋อง (6x325มล/แพ็ค) (Pepsi Zero Sugar Can) | AC6: 1202040016 | น้ำผลไม้เข้มข้น ซอสบ๊วย (1ลิตร/ขวด) (Plum Fruit Based Preparation) (Synova) | AE6: 1202050006 | อบเชยป่น (1กก/แพ็ค) (Cinnamon Powder) | AG6: 1101140002 | กรีนโอ๊ค ติดราก (kg) (Green Oak with Roots) (200-350กรัม/ต้น)
A7: Desserts | B7: CAT_6 | D7: 1101070006 | เนื้อวัวแองกัสขุนบด Fz. (1kg/pack) (Minced Beef Grain-Fed Angus Fz.) (Aro) | F7: 1102060905 | กาแฟเมล็ด (1กก/แพ็ค) (Coffee Beans Dark Roast) (Mae Jun Tai) | G7: 1101290006 | น้ำมันสลัด (3.3ลิตร/ขวด) (Salad Oil) (Mazola) | H7: 1101040003 | เนื้อปู่หิมะต้ม (500g/pack) (Snow Crab Meat Boiled) (Zuwai Kani Flake) | I7: 1101200204 | บริยอชโรล -Blueberry Yogurt (5 ชิ้น/ถาด) | J7: 1202100002 | Sapporo Draft Beer (20ltr/keg) (Sapporo Draft Beer) | K7: 1101210021 | ซอสพริกผสมหัวไชเท้า (360g/bt) (Momiji Oroshi) (Fukutoku) | M7: 1101010000 | ตลาดสดนอกรายการ (รหัสรอเปิด) | N7: 1202010010 | มะนาวแป้น สำหรับบาร์ (ลูก) (Lime) | O7: 1202020006 | น้ำมะพร้าวน้ำหอม (1ลิตร/ขวด) (Pure Coconut Juice) (Nam Hom) | P7: 1202070004 | นมข้าวโอ๊ต สูตรบาริสต้าเบลน (1ลิตร/กล่อง) (Barista Blend Oat Milk) (Oatside) | Q7: 1101180008 | เส้นอุด้งแช่แข็ง (250g/pack) (Udon Tenobe Nasari) | R7: 1101080006 | สันคอหมูสไลด์-6 แช่แข็ง เบทาโกร (kg) (Pork Collar Slices-6 Fz.) | S7: 1101090001 | ฟัวกราส์แช่แข็ง (kg) (Foie Gras Fz.) (400-700g/pack) | T7: 1101150014 | หมึกยักษ์ปรุงรสวาซาบิแช่แข็ง (1kg/pack) (Tako Wasabi Fz.) | U7: 1101160001 | ถั่วแระญี่ปุ่นแช่แข็ง (1kg/pack) (Edamame Fz.) | W7: 1101190006 | แป้งทอดกรอบ (1กก/แพ็ค) (Crispy Flour) (UFM) | X7: 1101020007 | ไข่ปลาเมนไทโกะปรุงรสปรุงรสแช่แข็ง เมนไทโกะ (500g/pack) (Mentaiko) | Y7: 1202110010 | สาเก คูโบตะ มันจู (720ml/bt) (Kubota Manju) (ASH) | Z7: 1101280013 | ซอสทงคัตสึ (1ลิตร/ขวด) (Tonkatsu Sauce) (Yamamori) | AA7: 1101030003 | กุ้งโบตั๋น (18-20pcs/2kg/pack) (Botan Ebi Fz.) | AB7: 1202080001 | โค้ก ออริจินัล กระป๋อง (24x325มล/แพ็ค) (Coke Original Can) | AC7: 1202040014 | น้ำผึ้งแท้ (760มล/ขวด) (Pure Natural Honey) (Vejpong) | AE7: 1202050001 | เกลือ ซีซอล์ท (60กรัม/ขวด) (Sea Salt Grinder) (McCormick) | AG7: 1101140004 | กรีนโอ๊ค มินิ (200กรัม/แพ็ค) (Green Oak Mini) (RPF)
A8: Draft Beer | B8: CAT_7 | D8: 1101070007 | เนื้อสันคอ Black Angus 100 วัน (kg) (Chuck Roll Black Angus 100 Days.) (Aus.) | F8: 1102060906 | กาแฟเมล็ด (1กก/แพ็ค) (Coffee Beans Dark Roast) (Rumudamo) | I8: 1101200205 | บริยอชโรล -Chocolate Dirty (5 ชิ้น/ถาด) | K8: 1101210007 | ถั่วมิกซ์นัทอบ ไม่ใส่เกลือ (454กรัม/แพ็ค) (Mixed Nuts Natural Toasted & Unsalted) (Nut Walker) | M8: 1101010014 | ปลากระพงแดงญี่ปุ่น (kg) (Madai) | N8: 1202010012 | มะม่วงน้ำดอกไม้ สุก (2-3 ลูก/กก) (Mango Nam Dok Mai Ripe) | O8: 1202020007 | น้ำรสมิกซ์เบอร์รี่ชนิดเข้มข้น (800มล/ขวด) (Mixed Berry Fruit Concentrate) (Sunquick) | P8: 1202070005 | นมถั่วเหลืองออร์แกนิครสจืด (250มล/กล่อง) (Soy Milk Organic) (โทฟุซัง) | Q8: 1101180002 | เส้นโซบะผสมชาเขียว นิชชิน (200g/pack) (Cha Soba Dried Noodle) (Nisshin) | R8: 1101080008 | สันนอกหมูแช่แข็ง B-31 เบทาโกร (kg) (Pork Loin B-31 Fz.) | S8: 1101090010 | สะโพกกระดูก (kg) (CK Thigh Boneless) | T8: 1101150013 | หมูทอดทงคัตสึแช่แข็ง (400g/pack) (Tonkatsu Pork) (FB Cook) | U8: 1101160011 | น้ำซุปปลาสกัดเข้มข้น (1ลิตร/กล่อง) (Handy Broth Awase JP) | W8: 1101190007 | แป้งทอดกรอบ (1กก/แพ็ค) (Crispy Flour) (วังทิพย์) | X8: 1101020005 | ไข่ปลาแซลมอนปรุงรสเม็ดใหญ่ (500g/pack) (Pink Salmon Roe Fz.) (MRD) | Y8: 1202110011 | สาเก คูโบตะ มันจู จุนไม ไดกินโจ (300ml/bt) (Kubota Manjyu Junmai Daiginjo) (ASH) | Z8: 1101280014 | ซอสบาร์บีคิวรสเกลือ (2.06ลิตร/ขวด) (Ebara E-basic Shio Dare) (BBQ Salt Sauce) | AB8: 1202080002 | โค้ก ไม่มีน้ำตาล กระป๋อง (24x325มล/แพ็ค) (Coke Zero Can) | AC8: 1202040015 | น้ำผึ้งแท้ (770มล/ขวด) (Pure Natural Honey) (Doi Kham) | AE8: 1202050007 | แยมส้มยูสุ ยูจาชา (1kg/jar) (Jam Yuja-Cha) (Danongwon) | AG8: 1101140069 | กล้วยหอม
A9: Dried Food/Grocery | B9: CAT_8 | D9: 1101070008 | เนื้อสันคอโคขุนสไลด์ 1.5mm. แช่แข็ง (500กรัม/แพ็ค) (Chuck Roll Sliced Fz.1.5 mm.) (Com.B) | F9: 1102060907 | กาแฟเมล็ด (1กก/แพ็ค) (Coffee Beans Dark Roast) (Whisky) | I9: 1101200206 | บริยอชโรล -Strawberry (5 ชิ้น/ถาด) | K9: 1101210008 | ถั่วลิสง (500กรัม/แพ็ค) (Peanuts Peeled) | M9: 1101010019 | ปลาชิมาอาจิ (kg) (Shima Aji) | N9: 1202010009 | มิกซ์เบอร์รีแช่แข็ง (1กก/แพ็ค) (Mixed Berries Fz.) (Aro) | O9: 1202020011 | น้ำสับปะรด (Tipco) (Pineapple Juice) (3x970ml/pack) | P9: 1202070007 | นมสด (1ลิตร/ขวด) (Milk Fresh Pasteurized) (mMilk) | Q9: 1101180004 | เส้นโซบะอบแห้ง (200g/pack) (Yamatmo Soba Dried Noodles) (Higashimaru) | R9: 1101080007 | สามชั้นแผ่น B-9 เบทาโกร (kg) (Pork Belly) | S9: 1101090012 | หนังไก่แผ่น BB เบทาโกร (1kg/pack) (CK Sheet Skin) | T9: 1101150002 | เนื้อปูเทียมแช่แข็ง (1kg/pack) (Crab Sticks Fz.) (Aro) | U9: 1101160013 | น้ำซุปสาหร่ายคอมบุสกัดเข้มข้น (1ลิตร/กล่อง) (Handy Broth Kombu JP) | W9: 1101190010 | แป้งมันสำปะหลัง (1กก/แพ็ค) (Tapioca Starch) (Baiyok) | X9: 1101020008 | ไข่หอยเม่น (อูนิ) (250g/pack) (Uni Bafun Hamanaka) | Y9: 1202110012 | สาเก คูโบตะ มันจู จุนไม ไดกินโจ (720ml/bt) (Kubota Manjyu Junmai Daiginjo) (ASH) | Z9: 1101280060 | ซอสปรุงรส พิซซ่าญี่ปุ่น โอโกโนมิ (300กรัมx12ขวด/ลัง) (Okonomi Sauce) (Otafuku) | AB9: 1202080005 | โซดา สิงห์ (24x325มล/แพ็ค) (Soda Singha) | AC9: 1202040017 | น้ำหวานเข้มข้น กลิ่นสละ (710มล/ขวด) (Concentrated Sala Flavoured Syrup) (Hale’s Blue Boy) | AE9: 1202050002 | ไข่มุกป๊อป รสสตรอว์เบอร์รี่ (_ _กรัม/ขวด) (Popping Boba Strawberry) (Tenju) | AG9: 1101140011 | กะหล่ำปลี (kg) (Cabbage White) (0.5-1กก/หัว)
A10: Eggs | B10: CAT_9 | D10: 1101070001 | เนื้อแองกัส Teys Black Cap MB4+ (kg) (Teys Black Angus Grain Fed Rump Cap MB4+) (Aus.) | F10: 1202060002 | กาแฟเมล็ด คั่วเข้ม (1กก/แพ็ค) (Coffee Beans Dark Roast) | I10: 1101200207 | บริยอชโรล -Strawberry Milk (5 ชิ้น/ถาด) | K10: 1101210009 | ถั่วลิสงบดชนิดละเอียด (1กก/ขวด) (Peanut Butter Creamy) (Skippy) | M10: 1101010032 | ปลาชิมาฮอกเกะแดดเดียว (300-350g/pack) (Shima Hokke Sun-dried) | N10: 1202010013 | ราสเบอร์รี่แช่แข็ง (1กก/แพ็ค) (Raspberry Fz.) (Aro) | O10: 1202020009 | น้ำส้มคั้นแท้ 100% (1ลิตร/ขวด) (Orange Juice Pure Pasteurized) (Smile) | P10: 1202070009 | นมสด (2ลิตร/ขวด) (Milk Fresh Pasteurized) (Meiji) | Q10: 1101180005 | เส้นโซบะอบแห้ง สีชมพู (100g/pack) (Dried Noodles) (Pink Shiso Soba) | R10: 1101080011 | หมูบด เนื้อแดง B-13 เบทาโกร (kg) (Pork Minced) | S10: 1101090011 | หัวใจ (kg) (CK Hearts) | T10: 1101150003 | เบคอนสดแช่แข็ง (Bacon Fresh Fz) (BTG) | U10: 1101160012 | น้ำซุปสุกี้ญี่ปุ่น (1kg/pack) (Sukiyaki Sauce) (Yamamori) | W10: 1101190011 | แป้งเทมปุระ (1kg/pack) (Tempurako Agejozu) (Nissin) | Y10: 1202110007 | สาเก คูโบตะ เซนจู กิงโจ (300ml/bt) (Kubota Senjyu Ginjo) (ASH) | Z10: 1101280016 | ซอสปรุงรสพื้นฐานหน้าข้าวต่างๆ (2.18ลิตร/ขวด) (Ebara E-Basic Donburi No Tare) | AC10: 1202040006 | น้ำเชื่อม (1.8ลิตร/ถุง) (Natural Cane Syrup) (Mitr Phol) | AG10: 1101140006 | กะเพรา (kg) (Hot Basil)
A11: Fish | B11: CAT_10 | F11: 1202060001 | กาแฟเมล็ด ดิบ (50กก/กระสอบ) (Coffee Bean Raw) | I11: 1101200208 | บริยอชโรล -Tiramisu (5 ชิ้น/ถาด) | K11: 1101210011 | ผงฟู สูตรดับเบิลแอ็คติ้ง (1กก/แพ็ค) (Baking Powder Double Acting) (Best Foods) | M11: 1101010018 | ปลาช่อนทะเล (ซูกิ) (_ _กรัม/ตัว) (Cobia Fish) (Sugi) | N11: 1202010014 | ลิ้นจี่ในน้ำเชื่อม (565กรัม/กระป๋อง) (Lychee in Syrup) (Aro) | O11: 1202020010 | น้ำส้มยูซุคั้นสด 100% (1ลิตร/ขวด) (Yuzu Fresh 100%) | P11: 1202070008 | นมสด (2ลิตร/ขวด) (Milk Fresh Pasteurized) (mMilk) | Q11: 1101180003 | เส้นโซบะเหลือง (_ _g/pack) (Yellow Soba Noodles) (Ramen Noodles) | R11: 1101080009 | ไส้หมู เบทาโกร (1kg/pack) (Pork Small Intestines) | S11: 1101090013 | อกไก่เนื้อล้วนติดหนัง (kg) (CK Breast Boneless Skin-on) | T11: 1101150004 | เบคอนหมูเดอลุกซ์ เบทาโกร (kg) (Pork Bacon) (BTG) | U11: 1101160015 | ผงสาหร่ายสไปรูลิน่าสีฟ้า (50g/pack) (Blue Spirulina Powder) | W11: 1101190008 | แป้งเทมปุระ (1กก/แพ็ค) (Tempura Mix Powder) (Yamamori) | Y11: 1202110008 | สาเก คูโบตะ เซนจู กิงโจ (720ml/bt) (Kubota Senjyu Ginjo) (ASH) | Z11: 1101280015 | ซอสปรุงรสหวาน คิคโคแมน (1.8ลิตร/ขวด) (Aji-Mirin Sweet Cooking Rice Seasoning) (Kikkoman) | AC11: 1202040010 | น้ำเชื่อม กลิ่นพีช (750มล/ขวด) (Peach Syrup) (Senorita) | AG11: 1101140012 | ขิงแก่ เบอร์ใหญ่ (kg) (Ginger Large)
A12: Fruits for Bar | B12: CAT_11 | F12: 1202060003 | ครื่องดื่มธัญญาหารสำเร็จรูปชนิดผง รสดั้งเดิม (12ซองx25กรัม/แพ็ค) (Instant Cereal Drink Powder Original Flavor) (Nesvita) | I12: 1101200212 | บริยอชโรล -Yogurt Lemon Cream (5 ชิ้น/ถาด) | K12: 1101210016 | พริกผสม 7 สี (300g/pack) (Shichimi Togarashi) (Amari) | M12: 1101010020 | ปลาซันมะ (kg) (Pacific Saury) (Sanma) | N12: 1202010018 | สตรอเบอร์รี่สด (250กรัม/แพ็ค) (Strawberries Fresh) | O12: 1202020008 | น้ำส้มเข้มข้น ซันควิก (1ลิตร/ขวด) (Concentrated Orange Juice) (Sunquick) | P12: 1202070010 | นมสด (5ลิตร/แกลลอน) (Milk Fresh Pasteurized) (Meiji) | R12: 1101080010 | ไส้อ่อนหมู เบทาโกร (1kg/pack) (Pork intestines) | S12: 1101090006 | เนื้อไก่บีแอล เบทาโกร (kg) (CK Boneless Leg Kakugiri) | T12: 1101150005 | เบคอนหมูเดอลุกซ์รมควัน Betagro (1kg/pack) (Smoked Pork Bacon Deluxe) (BTG) | U12: 1101160020 | มันปูญี่ปุ่นปรุงรสสำหรับย่าง (150g/pack) (Kani Miso Yaki JP) | W12: 1101190009 | แป้งเทมปุระ (450กรัม/แพ็ค) (Tempura Ko) (Nissin) | Y12: 1202110013 | สาเก คูโบต้า เซ็นจู (300ml/bt) (Kubota Senjyu) (ASH) | Z12: 1101280018 | ซอสผิวส้มยูสุผสมพริก (60กรัม/ขวด) (Yuzu Kosho) (Fujijin) | AC12: 1202040011 | น้ำเชื่อม กลิ่นมะพร้าว (750มล/ขวด) (Coconut Flavoured Syrup Nam Hom) (Senorita) | AG12: 1101140014 | ข่าอ่อน (kg) (Galangal Young) (2-3ซม/ชิ้น)
A13: Juices | B13: CAT_12 | F13: 1202060006 | ชาข้าวคั่วผสมมัทฉะ (200กรัม/แพ็ค) (Itoen Oi Ocha Uji Matcha Iri) | I13: 1101200209 | พาย -Blueberry Cheese (3 lbs.) (Premium) | K13: 1101210015 | พริกูป่น (500กรัม/แพ็ค) (Ground Chili) (Raithip) | M13: 1101010021 | ปลาซาบะนอร์เวย์แช่แข็ง (400-600กรัม) (Saba Fz.) (NWG) | N13: 1202010017 | สตรอเบอร์รี่แช่แข็ง (1กก/แพ็ค) (Strawberry Fz.) (Aro) | O13: 1202020013 | สมูทตี้แช่แข็ง -น้ำบลูเบอร์รี่องุ่น (10ชิ้นx_ _กรัม/กล่อง) (Smoothies Fz -Blueberries Grapes) (Synova) | P13: 1202070011 | นมอัลมอนด์ (946มล/กล่อง) (Almond Milk Breeze Barista Blend) (Blue Diamond) | S13: 1101090005 | เนื้อไก่บีแอลเค (BLK) (kg) (CK Boneless Leg Kakugiri) (30-35กรัม/ชิ้น) | T13: 1101150001 | ไข่ม้วนญี่ปุ่น / ไข่หวาน (500g/pack) (Tamago Yaki Fz.) (Momiji) | U13: 1101160018 | มันปูปรุงรส (100g/pack) (Kani Miso) (Maruyo) | Y13: 1202110014 | สาเก คูโบต้า เซ็นจู (720ml/bt) (Kubota Senjyu) (ASH) | Z13: 1101280019 | ซอสพริกเผ็ดกลาง (900กรัม/ขวด) (Chilli Sauce) (Sriracha) | AC13: 1202040012 | น้ำเชื่อม กลิ่นลิ้นจี่ (750มล/ขวด) (Lychee Flavored Syrup) (Senorita) | AG13: 1101140013 | ข้าวโพดหวาน (kg) (Sweet Corn)
A14: Milk and Whipping Cream | B14: CAT_13 | F14: 1202060008 | ชาข้าวคั่วผสมมัทฉะ (400กรัม/แพ็ค) (Roasted Rice Green Tea w/Matcha) (Iri Genmaicha) | I14: 1101200210 | พาย -Blueberry Oreo (3 lbs.) | K14: 1101210012 | พริกแกงเขียวหวาน (กก) (Green Curry Paste) | M14: 1101010022 | ปลาน้ำดอกไม้ญี่ปุ่น (_ _ กรัม/ตัว) (Kamasu Fish) | N14: 1202010019 | สับประรด ตราดสีทอง (kg) (Pineapple) (Trat Golden) | O14: 1202020014 | สมูทตี้แช่แข็ง -น้ำลิ้นจี่ไลม์ (10ชิ้นx_ _กรัม/กล่อง) (Smoothies Fz -Lychee Lime) (Synova) | P14: 1202070006 | นมเปรี้ยวสูตรโปรตีน รสออริจินัล (3ขวดx300มล/แพ็ค) (Yogurt Original Protein) (Betagen) | S14: 1101090003 | โครงไก่ (กก) (Chicken Bone) | T14: 1101150012 | ไส้กรอกรมควัน สไตล์ญี่ปุ่น (400g/pack) (Smoked Sausage Japanese Style) (Bucher) | U14: 1101160019 | มันปูปรุงรสแช่แข็ง (300g/pack) (Kani Miso Fz.) (Crab Miso Fz.) | Y14: 1202110015 | สาเก เซนจู (1800ml/bt) (Senju) (Kubota) | Z14: 1101280020 | ซอสภูเขาทองฝาเขียว (3ลิตร/แกลลอน) (Seasoning Soy Sauce) (Golden Mountain) | AC14: 1202040013 | น้ำเชื่อม กลิ่นสตอเบอร์รี (750มล/ขวด) (Strawberry Flavored Syrup) (Senorita) | AG14: 1101140016 | ดอกไม้ญี่ปุ่น (kg) (Veg Kogiku) (ดอกเบญจมาศ)
A15: Noodles | B15: CAT_14 | F15: 1202060009 | ชาซีลอน 121 (_ _กรัม/แพ็ค) (Tea Ceylon 121) | I15: 1101200211 | พาย -Mayongchid Cheese (ea) | K15: 1101210013 | พริกแดงป่นผสมงา S&B (300g/pack) (Assorted Chili Pepper) (Nanami Togarachi) | M15: 1101010023 | ปลามงแซ่ (โยรอย อาจิ) (_ _กรัม/ตัว) (Yoroi Aji Fish) | N15: 1202010020 | สับปะรดภูแลแช่แข็ง (1กก/แพ็ค) (Pineapple Fz.) (Phu Lae) | O15: 1202020015 | สมูทตี้แช่แข็ง -น้ำสตรอเบอรี่ (10ชิ้นx_ _กรัม/กล่อง) (Smoothies Fz -Strawberry) (Synova) | P15: 1102070016 | ผงโยเกิร์ต 1 (กก/แพ็ค) (Yogurt Powder) | T15: 1101150011 | ไส้กรอกหมูญี่ปุ่น อาราบิกิ (500g/pack) (Pork Sausage JP) (Arabiki) | U15: 1101160017 | มิโซะ มันกุ้งล็อบสเตอร์ปรุงรส (300g/pack) (Lobster Miso) | Y15: 1202110002 | สาเก เดนชิน ริน จุนไม ไดกินโจ (720ml/bt) (Denshin 'Rin' Junmai Daiginjo) | Z15: 1101280021 | ซอสมะเขือเทศ (1กก/แพ็ค) (Tomato Sauce) (Roza) | AC15: 1202040007 | น้ำเชื่อม กลิ่นเฟรชมิ้นท์ (750มล/ขวด) (Fresh Mint Flavored Syrup) (Senorita) | AG15: 1101140017 | ดอกไม้ทานได้ (25กรัม/แพ็ค) (Edible Flowers) (Edi)
A16: Pork | B16: CAT_15 | F16: 1202060012 | ชาส้มเกาหลี (_ _กรัม/แพ็ค) ( Yuzu Tea Korean) | I16: 1101200020 | เค้ก -Almond coffee cake (3 lbs.) | K16: 1101210017 | พริกแห้งจินดา (กก) (Dried Jinda Chili) | M16: 1101010024 | ปลามาได (1Kg) (Red Sea Bream JP) (Madai) | N16: 1202010015 | ส้มจีน นาเวล/วาเลนเซีย (กก) (Orange Navel/Valencia) | O16: 1102020016 | สมูทตี้แช่แข็ง -น้ำส้มผสมเนื้อสับปะรด (10ชิ้นx_ _กรัม/กล่อง) (Smoothies Fz -Pineapple Orange) (Synova) | P16: 1102070017 | ผงโยเกิร์ต 2 (กก/แพ็ค) (Yogurt Powder) | U16: 1101160021 | ยำสาหร่ายญี่ปุ่น (1kg/pack) (Sesame Seaweed Seasoned) (Chuka Wakame/Yamamoto) | Y16: 1202110003 | สาเก เด็นชิน ยูกิ จุนไม กินโจ (300ml/bt) (Denshin Yuki Junmai Ginjo) | Z16: 1101280059 | ซอสมะเขือเทศ (2.2กก/แกลลอน) (Tomato Sauce) (Heinz) | AC16: 1202040008 | น้ำเชื่อม กลิ่นเฟร้นช์วานิลลา (750มล/ขวด) (French Vanilla Syrup) (Torani) | AG16: 1101140020 | ตะไคร้ (kg) (Lemongrass) (40-42ซม/ต้น)
A17: Poultry | B17: CAT_16 | F17: 1202060007 | ชาเขียวญี่ปุ่นผสมข้าวคั่วเกรดพรีเมียม (300กรัม/แพ็ค) (Ito Green Tea With Roasted Rice) (Itoen Genmaicha) | I17: 1101200003 | เค้ก -Banoffee | K17: 1101210018 | พริกแห้งหั่นเส้น ตรามือที่1 (20กรัม/แพ็ค) ( Dried Chili) (Nguan Soon) | M17: 1101010025 | ปลาหางเหลือง ส่วนคอ แช่แข็ง (180กรัม/แพ็ค) (Yellow Tail Neck Meat Fz.) (Hamachi Kama) | N17: 1202010016 | ส้มซันคิสต์ (_ _ลูก/กก) (Orange Sunkist) | O17: 1202020012 | สมูทตี้แช่แข็ง -น้ำเสาวรสมะม่วง (10ชิ้นx_ _กรัม/กล่อง) (Smoothies Fz -Passion Fruits Mango) (Synova) | P17: 1202070013 | วิปปิ้งครีม (1ลิตร/กล่อง) (Whipping Cream) (Anchor) | U17: 1101160023 | สาหร่ายทะเลคอมบุ สำหรับทำซุป (100g/pack) (Dried Kombu Seaweed for Soup) (Taberu) | Y17: 1202110004 | สาเก เด็นชิน ยูกิ จุนไม กินโจ (720ml/bt) (Denshin Yuki Junmai Ginjo) | Z17: 1101280022 | ซอสยากิโซบะ (1ลิตร/ขวด) (Yakisoba Sauce) (Yamamori) | AC17: 1202040009 | น้ำเชื่อม กลิ่นเฮเซลนัท (750มล/ขวด) (Hazelnut Syrup) (Torani) | AG17: 1101140022 | ต้นหอมญี่ปุ่น (kg) (Spring Onions Japanses)
A18: Processed Food Meat | B18: CAT_17 | F18: 1202060004 | ชาเขียวมัทฉะ Y-1 (1กก/แพ็ค) (Maccha Greesn Tea Y-1) (Ujinotsuyu) | I18: 1101200004 | เค้ก -Biskoff Cheese Cake (2 lbs.) | K18: 1101210014 | พริกไทยดำเม็ด (1กก/แพ็ค) (Pepper Corns Black) (No.1 Hand) | M18: 1101010026 | ปลาหางเหลืองแช่แข็ง (2-2.5kg/ea) (Yellow Tail Fz.) (Hamachi) | N18: 1202010021 | อโวคาโดผ่าครึ่งแช่แข็ง (1กก/แพ็ค) (Halved Avocado Fz.) (Aro) | O18: 1102020017 | สมูทตี้แช่แข็ง -แมงโก้แทงโก้ (10ชิ้นx_ _กรัม/กล่อง) (Smoothies Fz -Mango Tango) (Synova) | P18: 1202070014 | วิปปิ้งครีมผง ชนิดจืด (500กรัม/แพ็ค) (Whipping Cream Powder) (Dreamy) | U18: 1101160026 | สาหร่ายผงหยาบ (100g/pack) (Dried Seaweed Aonori) (Tabaru) | Y18: 1202110016 | สาเก เมนจู (1800ml/bt) (Menju) (Kikusui) | Z18: 1101280023 | ซอสวูสเตอร์ (1ลิตร/ขวด) (Worcester Sauce) (Yamamori) | AC18: 1202040005 | นํ้าเชื่อม กลิ่นคาราเมล (750มล/ขวด) (Caramel Syrup) (Torani) | AG18: 1101140023 | ต้นหอมไทย A (kg) (Thai Spring Onions A) (ยาว 38-42ซม/ต้น)
A19: Processed Food Other | B19: CAT_18 | F19: 1202060005 | ชาเขียวมัทฉะพรีเมี่ยม (1กก/แพ็ค) (Green Tea Matcha Excellent) (Matchazuki) | I19: 1101200005 | เค้ก -Blueberry Cheese Pie (3 lbs.) | K19: 1101210002 | เกล็ดขนมปัง (1กก/แพ็ค) (Bread Crumbs) (Farmhouse) | M19: 1101010028 | ปลาอาจิ (kg) (Horse mackare) (Aji) | N19: 1202010002 | เชอร์รี่แดงมีก้าน (737กรัม/ขวด) (Cherries Maraschino With Stem ) (Castella) | P19: 1202070012 | โยเกิร์ต รสธรรมชาติ (135กรัม/ถ้วย) (Yogurt Original Flavor) (Dutchie) | U19: 1101160029 | สาหร่ายห่อข้าว (25sheetx4/pack) (Roasted Seaweed Sheets) (Shimamto) | Y19: 1202110018 | สาเก เอมิชิกิ เซนเซชั่น แบล็ค (720ml/bt) (Emishiki Sensation Black) | Z19: 1101280024 | ซอสหอยนางรม สูตร 1 (4.5กก/แกลลอน) (Oyster Sauce F.1) (นกขั้วโลก/Polar Birds) | AC19: 1102040019 | ไซรัป กลิ่นกลิ่นกุหลาบ ลิน (750ml/bt) (Rose Flavored Syrup) (Lin) | AG19: 1101140024 | ต้นอ่อนทานตะวัน (kg) (Sunflower Sprouts)
A20: Ready to Drinks | B20: CAT_19 | F20: 1202060010 | ชาเทพพนม (1กก/แพ็ค) (ChaTheppanom) (121) | I20: 1101200006 | เค้ก -Blueberry Crumble Cheese Cake (3 lbs.) | K20: 1101210020 | แปะก๊วย (กก) (Ginkgo Nuts) | M20: 1101010029 | ปลาอินทรีญี่ปุ่น (ปลาซาวาระ) (_ _g/ea) (Sawara Fish/Spanish Mackerel JP) | N20: 1202010004 | เนื้อมะพร้าวแบบแผ่นแช่แข็ง (1กก/แพ็ค) (Coconut meat) (All Coco) | U20: 1101160028 | สาหร่ายห่อข้าว (50sheet/pack) (Roasted Seaweed Sheets) (Grade A.) | Y20: 1202110020 | สาเก โกเซ็นชู ยูซุ (500ml/bt) (Gozenshu Yuzu Sake) | Z20: 1101280017 | ซอสเปลือกส้มยูซุญี่ปุ่น และพริกเขียว เฮาส์ เรียวเตอิ ยูซุ โคโช | AC20: 1202040018 | ไซรัป กลิ่นข้าวคั่วญี่ปุ่น (6x830มล/กล่อง) (JP Rice Flavoured Syrup) (Synova) | AG20: 1101140025 | ถั่วฝักยาว (kg) (Long Beans) (50-60ซม/เส้น)
A21: Rice/Flour | B21: CAT_20 | F21: 1202060011 | ชาเทพพนม (1กก/แพ็ค) (ChaTheppanom) (V4) | I21: 1101200007 | เค้ก -Brownie Cheese Cake (2 lbs.) | K21: 1101210019 | แยมรสส้ม (340กรัม/ขวด) (Jam Orenge) (Best Foods) | M21: 1101010030 | ปลาฮามาจิแล่ (1.8-2.5kg/pc) (Hamachi Fillet) | N21: 1202010003 | แตงโม (3.5กก/ลูก) (Watermelon) | U21: 1101160030 | สาหร่ายห่อข้าวโนริ | Y21: 1202110017 | สาเก ไดกินโจ (1800ml/bt) (Daiginjo) | Z21: 1101280025 | ซอสเห็ดผสมเห็ดทราฟเฟิล (500กรัม/ขวด) (Mushroom & Traffles Sauce) (Morra Tartufalba) | AG21: 1101140030 | บล็อคโคลี่นอก (kg) (Broccoli Imported)
A22: Roe Fish/Shrimp | B22: CAT_21 | F22: 1202060016 | ทไวนิงส์ ชาอิงลิชเบรกฟาสต์ (25ซองx2กรัม/กล่อง) (Tea English Breakfast) | I22: 1101200008 | เค้ก -Caramel Macadamia Cheese Cake (2 lbs.) | K22: 1101210010 | ใบโอบะแห้ง (20pcs/แพ็ค) (Dried Houba Leaves) | M22: 1101010015 | ปลาเงิน ปลาชิราอุโอะ แช่แข็ง 5-7 cm (1kg/pack) (Silver Fish) (Shirauo) | N22: 1202010006 | แบล็คเบอร์รี (100กรัม/แพ็ค) (Blackberry) (RPF) | U22: 1101160027 | สาหร่ายเส้น (โรยหน้า) (100g/pack) (Roasted Seaweed Shredded ) (Taberu) | Y22: 1202110022 | เหล้าบ๊วย ชาโอย่า เอ็กซ์ตร้า เยียร์ (700ml/bt) (Choya Extra Years) (Umeshu) | Z22: 1101280026 | น้ำก๋วยเตี๋ยวสำเร็จรูปเข้มข้น น้ำใส (6ถุงx350มล/แพ็ค) (Clear Noodle Soup Concentrated ) (FaThai) | AG22: 1101140033 | ผัก Tatekatsura (kg)
A23: Sake | B23: CAT_22 | F23: 1202060013 | ทไวนิงส์ ชาเขียวมะลิ (25ซองx2กรัม/กล่อง) (Tea Jasmine Green) | I23: 1101200009 | เค้ก -Cherry Black Forest (2 lbs.) | M23: 1101010016 | ปลาเงินแช่แข็ง (kg/pack) (Silver Fish) (Shirauo Fz.) | U23: 1101160024 | สาหร่ายโทซากะ สีเขียว (500g/pack) (Tosaki Nori Green Salted) | Y23: 1202110021 | เหล้าบ๊วย อายะ อุเมะ ลิเคียวร์ (500ml/bt) (Aya Ume Liqueur) | Z23: 1101280027 | น้ำจิ้มปิ้งย่าง ยากินิกุ ทาเระ (1ลิตร/ขวด) (Yakinikutare Grilled Sauce) (Yamamori) | AG23: 1101140034 | ผักกวางตุ้งไต้หวัน (kg) (Pak Choi)
A24: Sauce & Seasonings | B24: CAT_23 | F24: 1202060014 | ทไวนิงส์ ชาเพียวคาโมไมล์ (25ซองx2กรัม/กล่อง) (Tea Pure Chamomile) | I24: 1101200010 | เค้ก -Chocolate Fudge | M24: 1101010001 | ปลาแซลมอน (5-6กก/ตัว) (Salmon Fresh) | U24: 1101160025 | สาหร่ายโทซากะ สีแดง (500g/pack) (Tosaki Nori Red Salted) | Z24: 1101280028 | น้ำตาลทรายขาว (1กก/แพ็ค) (White Sugar) (Mitr Phol) | AG24: 1101140035 | ผักกาดขาว (kg) (Cabbage White) (0.5-1กก/หัว)
A25: Shrimp | B25: CAT_24 | F25: 1202060015 | ทไวนิงส์ ชาเอิร์ลเกรย์ (25ซองx2กรัม/กล่อง) (Tea Earl Grey) | I25: 1101200011 | เค้ก -Chocolate Fudge (ea) | M25: 1101010017 | ปลาโฉมงาม (อุมาระอาจิ) (Umadsura Aji Fish) (Filefish) | U25: 1101160022 | สุกิยากิ โนะ ทาเระ (เอบาระ) (500ml/bt) (Sukiyaki No Tare) (Ebara) | Z25: 1101280030 | น้ำตาลอ้อยผสมน้ำตาลมะพร้าว (1กก/แพ็ค) (Cane Sugar Mixed with Coconut Sugar) (Mitr Phol) | AG25: 1101140036 | ผักกาดหอม (kg) (Lettuce) (RPF)
A26: Soft Drinks | B26: CAT_25 | F26: 1202060018 | ผงดาร์กช็อกโกแลตพรีมิกซ์ (500กรัม/แพ็ค) (Dark Chocolate Premix Powder) (Synova) | I26: 1101200012 | เค้ก -Dark Chocolate Cheese Cake (2 lbs.) | M26: 1101010027 | ปลาไหลญี่ปุ่นย่างซีอิ๊ว (140g/pack) (Roasted Eel) (Unagi Kabayaki) | U26: 1101160008 | เต้าหู้คินุ (300g/pack) (Tofu Kinu) (Ohayo) | Z26: 1101280029 | น้ำตาลเหลวมะพร้าว (1กก/แพ็ค) (Plam Sugar ) (Red Rose) | AG26: 1101140038 | ผักชีฝรั่ง (kg) (Parsley Long Leave)
A27: Syrup | B27: CAT_26 | F27: 1202060019 | ผงบ๊วยแท้ 100% บดละเอียด ไม่ผสมน้ำตาล (1กก/แพ็ค) (Plum Powder) | I27: 1101200013 | เค้ก -Flourless Red Velvet Cheese Cake | M27: 1101010031 | ปลาไหลย่างซีอิ๊ว ไซส์ 45P (Unagi Kabayaki) (205-225 กรัม/ชิ้น) (Eel Roasted) | U27: 1101160009 | เต้าหู้ทอดปรุงรส (อินาริ) (30pcs/pack) (Seasoned Fried Tofu) (Inari) | Z27: 1101280032 | น้ำปลาแท้ (1.5ลิตร/ขวด) (Fish Sauce) (Tiparos) | AG27: 1101140039 | ผักชีลาว (kg) (Dill)
A28: Tako/Squid | B28: CAT_27 | F28: 1202060020 | ผงมัทฉะเลมอน (500กรัม/แพ็ค) (Matcha Lemon Powder) | I28: 1101200014 | เค้ก -Matcha Red Bean | M28: 1101010005 | เนื้อปลาทูน่าบลูฟิน (kg) (Bluefin Tuna) (Akami) | U28: 1101160006 | เต้าเจี้ยวญี่ปุ่น ตราเด็ก (1kg/pack) (Soy Paste JP.) (Miso Paste) | Z28: 1101280033 | น้ำปลาแท้ (4.5ลิตร/แกลลอน) (Fish Sauce) (Tiparos) | AG28: 1101140037 | ผักชีไทย (kg) (Coriander Thai)
A29: Topping | B29: CAT_28 | F29: 1202060017 | ผงโกโก้ ชนิดสีเข้ม (440กรัม/แพ็ค) (Cocoa Powder) (Tulip) | I29: 1101200015 | เค้ก -Mayongchid | M29: 1101010006 | เนื้อปลาทูน่าบลูฟิน (kg) (Bluefin Tuna) (Chutoro) | U29: 1101160010 | เบสน้ำซุปเข้มข้นรสเกลือ (_ _ml/bt) (E-Basic Shio Ramen Soup) (Ebara) | Z29: 1101280031 | น้ำปลาแท้ (700มล/ขวด) (Fish Sauce) (Tiparos) | AG29: 1101140041 | ผักสลัดแก้ว (kg) (Iceberg Lettuce) (RPF)
A30: Uni/Shellfish | B30: CAT_29 | I30: 1101200016 | เค้ก -Orange Chinese New Year | M30: 1101010007 | เนื้อปลาทูน่าบลูฟิน (kg) (Bluefin Tuna) (Harakami) | U30: 1101160014 | เปลือกยูซุแช่แข็ง หั่นฝอย (100g/pack) (Yuzu Peel Shredded Fz.) (Kaneku Kizami) | Z30: 1101280034 | น้ำผึ้งแท้ (760มล/ขวด) (Natural Honey) (Vejpong) | AG30: 1101140042 | พริกขี้หนูสวนแดงเขียว เด็ดขั้ว (kg) (Bird Eye Chilli Red & Green Stemless)
A31: Vegetables | B31: CAT_30 | I31: 1101200017 | เค้ก -Raspberry Cake | M31: 1101010008 | เนื้อปลาทูน่าบลูฟิน (kg) (Bluefin Tuna) (Hon Maguro) | U31: 1101160016 | เฟรนช์ฟรายส์แช่แข็ง เส้นหยัก 12 มม. (6x2กก/แพ็ค/ลัง) (French Fries Crinkle Cut Fz.12mm.) | Z31: 1101280035 | น้ำมะขามเปียกเข้มข้น (1ลิตร/ขวด) (Tamarind Paste Concentrate) (Chua Hah Seng ) | AG31: 1101140043 | พริกจินดาเขียว เด็ดก้าน (kg) (Green Jinda Chili Stemless)
A32: Wasabi | B32: CAT_31 | I32: 1101200018 | เค้ก -Red Heart Valentine | M32: 1101010009 | เนื้อปลาทูน่าบลูฟิน (kg) (Bluefin Tuna) (Otoro) | Z32: 1101280037 | น้ำมันงา (4ลิตร/แกลลอน) (Sesame Oil) (Twin Elephant) | AG32: 1101140044 | พริกจินดาแดง เด็ดก้าน (kg) (Red Jinda Chili Stemless)
A33: Whiskey/Brandy | B33: CAT_32 | I33: 1101200019 | เค้ก -Strawberry Short Cake | M33: 1101010004 | เนื้อปลาทูน่าแช่แข็ง (kg) (Tuna Saku Fz.) | Z33: 1101280036 | น้ำมันงา (630มล/ขวด) (Sesame Oil) (Twin Elephant) | AG33: 1101140045 | พริกชี้ฟ้าเขียว (kg) (Green Spur Chili)
I34: 1101200101 | ไอศครีม -Cheat Day (4ltr/pail) | M34: 1101010010 | แก้มปลาบุรี (1kg) (Buri Kama) | Z34: 1101280038 | น้ำมันงารสเผ็ด (1650มล/ขวด) (LA-YU Chili Oil) (Kadoya) | AG34: 1101140046 | พริกชี้ฟ้าแดง (kg) (Red Spur Chili)
I35: 1101200102 | ไอศครีม -Here's Your Damn Good Chocolate (4ltr/pail) | Z35: 1101280039 | น้ำมันพริก ลายุ ชิลลี่ ออยล์ (_ _มล/ขวด) (La-Yu Chili Oil) (S&B) | AG35: 1101140047 | ฟักทองญี่ปุ่น (kg) (Pumpkin Japanese)
I36: 1101200103 | ไอศครีม -Tokyo Mist (4ltr/pail) | Z36: 1101280040 | น้ำส้มสายชู อเนกประสงค์ กลั่นจากธัญพืช (1.8ลิตร/ขวด) (Grain Kokumotsu Vinegar) (Mizgan) | AG36: 1101140051 | มะนาวเหลือง (200กรัม/ลูก) (kg) (Yellow Lemon)
I37: 1101200104 | ไอศครีม -Uji Matcha (4ltr/pail) | Z37: 1101280041 | น้ำส้มสายชูหมัก (20ลิตร/กล่อง) (Suehiro Grain Vinegar) (Mizkan) | AG37: 1101140050 | มะนาวแป้น (50ลูก/กก) (Lime)
Z38: 1101280042 | ผงชูรส (1กก/แพ็ค) (Monosodium Glutamate) (Ajinomoto) | AG38: 1101140067 | มะพร้าวน้ำหอมเขียว
Z39: 1101280043 | ผงชูรส (3กก/แพ็ค) (Monosodium Glutamate) (Ajinomoto) | AG39: 1101140070 | มะพร้าวเผา
Z40: 1101280046 | ผงปรุงรส รสไก่ (1.5กก/แพ็ค) (Chicken Seasoning Powder) (Ros Dee) | AG40: 1101140052 | มะละกอดิบ-แขกนวล (kg) (Papaya Raw -Khaek Nuan)
...

Sheet ItemMaster
A1: code | B1: display | C1: recipe_unit | D1: yield_pct
A2: 1101010000 | B2: 1101010000 | ตลาดสดนอกรายการ (รหัสรอเปิด) | C2: g | D2: 100
A3: 1101010001 | B3: 1101010001 | ปลาแซลมอน (5-6กก/ตัว) (Salmon Fresh) | C3: g | D3: 58
A4: 1101010002 | B4: 1101010002 | FG.เนื้อปลาแซลมอนสดแล่ (กก) (FG.Salmon Fillet Fresh) (แล่โดย.Chef) | C4: g | D4: 58
A5: 1101010003 | B5: 1101010003 | FG.หัวปลาแซลมอนสด (หัว) | C5: pc | D5: 100
A6: 1101010004 | B6: 1101010004 | เนื้อปลาทูน่าแช่แข็ง (kg) (Tuna Saku Fz.) | C6: g | D6: 100
A7: 1101010005 | B7: 1101010005 | เนื้อปลาทูน่าบลูฟิน (kg) (Bluefin Tuna) (Akami) | C7: g | D7: 88
A8: 1101010006 | B8: 1101010006 | เนื้อปลาทูน่าบลูฟิน (kg) (Bluefin Tuna) (Chutoro) | C8: g | D8: 88
A9: 1101010007 | B9: 1101010007 | เนื้อปลาทูน่าบลูฟิน (kg) (Bluefin Tuna) (Harakami) | C9: g | D9: 88
A10: 1101010008 | B10: 1101010008 | เนื้อปลาทูน่าบลูฟิน (kg) (Bluefin Tuna) (Hon Maguro) | C10: g | D10: 88
A11: 1101010009 | B11: 1101010009 | เนื้อปลาทูน่าบลูฟิน (kg) (Bluefin Tuna) (Otoro) | C11: g | D11: 88
A12: 1101010010 | B12: 1101010010 | แก้มปลาบุรี (1kg) (Buri Kama) | C12: g | D12: 100
A13: 1101010011 | B13: 1101010011 | ครีบปลากระเบนแช่เข็ง 13-16 cm (500g/Pack) (Stingray Fin Fz.) (Ei Hire) | C13: g | D13: 95
... A626: 1808010001 | B626: 1808010001 | ADK -WT - 30001 AIR DAIKIN รุ่น FAVF30XV2S | C626: set | D626: 100
A627: 1808010002 | B627: 1808010002 | AML - CC -48003 AIR MR. SLIM รุ่น PLY-M48EALM | D627: 100
A628: 1808020001 | B628: 1808020001 | COBBLE STONE GRANITE | D628: 100
A629: 1808020002 | B629: 1808020002 | DISH WASHING | D629: 100
A630: 1808020003 | B630: 1808020003 | EXHAUST HOOD | D630: 100
A631: 1808020004 | B631: 1808020004 | HOOD | D631: 100
A632: 1808020005 | B632: 1808020005 | MAIN KITCHEN | D632: 100
A633: 1808020006 | B633: 1808020006 | PREPARATION AREA | D633: 100
A634: 1808020007 | B634: 1808020007 | SUSHI BAR ,BAR AREA | D634: 100
A635: 1808020008 | B635: 1808020008 | ก/บ ผนัง ARGENTA 20x31.6 ซม.CAIRO MARFIL | D635: 100
A636: 1808020009 | B636: 1808020009 | ก/บ พื้น ABK 13.5x80ซม. SOLERAS AVANA RETT S1R48250 | D636: 100
A637: 1808020010 | B637: 1808020010 | ก/บ พื้น GVV 60x60cm BAY MIST BRUSHED R11 C600156 | D637: 100
A638: 1808020011 | B638: 1808020011 | ก/บ พื้น SUPER 30x60cm PERLATO CREAM POL TTNM3404 | D638: 100
... A774: 1808160003 | B774: 1808160003 | ค่าโปรแกรม BPLUS HRM | D774: 100
A775: 1101140067 | B775: 1101140067 | มะพร้าวน้ำหอมเขียว | C775: pice | D775: 100
A776: 1101140068 | B776: 1101140068 | แอปเปิ้ล | C776: pice | D776: 100
A777: 1101140069 | B777: 1101140069 | กล้วยหอม | C777: pice | D777: 100
A778: 1101140070 | B778: 1101140070 | มะพร้าวเผา | C778: pice | D778: 100
A779: 1101040006 | B779: 1101040006 | ขาปูทาราบะ | C779: pc | D779: 100
A780: 1101160030 | B780: 1101160030 | สาหร่ายห่อข้าวโนริ | C780: pc | D780: 100
A781: 1202050008 | B781: 1202050008 | ริชส์ นอนแดรี่ ครีมเมอร์ 454 ก. | C781: g | D781: 100
A782: 1202100006 | B782: 1202100006 | Erdinger Braohaus | C782: หน่วยเล็ก | D782: 100
A783: 1202060904 | B783: 1202060904 | กาแฟ MYANMAR+BRAZIL 1000g | C783: หน่วยเล็ก | D783: 100
